Workbook

Sheet Instructions
A1: SYSTEM1 REQUIREMENT SOURCE REGISTRY
A2: Operator quick start, status definitions, examples, and recovery guidance
A4: QUICK START
A5: 1 | B5: Close Excel | C5: Save and close this workbook before running System1. If Excel is open, the program safely defers without writing.
A6: 2 | B6: Open the work queue | C6: Use Human Operation Desktop. The Dashboard is status-only and never runs local code.
A7: 3 | B7: Complete the yellow cells | C7: Choose operator_action, enter operator, and add operator_note when rejecting, returning, or reporting an error.
A8: 4 | B8: Run Routine Cycle | C8: Use Run System - macOS.command or Run System - Windows.cmd. checked_at is filled automatically.
A9: 5 | B9: Confirm the result | C9: Review program_status and program_result. Completed rows remain in the audit trail and are hidden.
A11: WORKBOOK STRUCTURE
A12: Instructions | B12: This sheet | C12: Quick Start, statuses, operator cases, examples, and recovery.
A13: Categories | B13: Controlled vocabulary | C13: Dropdown values and category definitions used by the registry.
A14: Source Register | B14: Program-generated source state | C14: The program-managed block must not be edited directly. Human-governed corrections flow through Human Operation Desktop.
A15: Dashboard | B15: Read-only status view | C15: Key source states, open work, automation status, and QA history.
A16: Human Operation Desktop | B16: Only operator work area | C16: All human decisions, corrections, candidate acceptance, manual-file actions, and Random QA.
A18: STATUS DEFINITIONS
A19: download_status | B19: SUCCESS / FAIL / PAYWALL_BLOCKED | C19: Collection result. Selection and download remain independent.
A20: selection_status | B20: INCLUDE / PENDING / EXCLUDE | C20: Effective source-list state. INCLUDE requires a valid current snapshot and completed governance checks.
A21: program_status | B21: PENDING / WAITING_FOR_HUMAN / NEEDS_REPLAN / APPLIED / REJECTED | C21: Open statuses remain visible. Final statuses remain stored but hidden.
A22: operator_action | B22: Varies by task type | C22: Source/selection review: APPLY or RETURN. Candidate/manual intake: ACCEPT or REJECT. Random QA: CORRECT or INCORRECT.
A24: OPERATOR CASES
A25: Existing source review | B25: Inspect the source and requested correction | C25: Unhide SOURCE CORRECTIONS only when the task asks for field changes, then choose APPLY or RETURN.
A26: Selection review | B26: Choose INCLUDE, PENDING, or EXCLUDE | C26: Unhide SOURCE CORRECTIONS, complete operator_selection_decision, and add a note when remaining PENDING.
A27: New source candidate | B27: Accept or reject the candidate | C27: Unhide CANDIDATE DETAILS, complete missing fields, then choose ACCEPT or REJECT. No new source is auto-accepted.
A28: Manual file intake | B28: Drop a file into Data/00_Human_Intake | C28: Routine Cycle identifies it, searches registered metadata for an official route, and creates a task for missing information.
A29: Manual replacement/paywall | B29: Provide only an authorised file | C29: The current valid source is retained unless the replacement validates successfully. System1 never bypasses a paywall.
A30: Random QA | B30: Verify the sampled source record and file | C30: Choose CORRECT or INCORRECT. An incorrect result creates a correction task.
A32: EXAMPLES
A33: Example 1 | B33: Selection review | C33: Unhide SOURCE CORRECTIONS, choose operator_selection_decision, select APPLY, enter your name, and run Routine Cycle.
A34: Example 2 | B34: Failed retrieval | C34: Verify the official URL, add a corrected retrieval URL if available, select APPLY, and run Routine Cycle. A failed retry preserves the current valid file.
A35: Example 3 | B35: New manual file | C35: Copy the file to Data/00_Human_Intake, run Routine Cycle, complete the candidate task, and choose ACCEPT only after provenance and applicability are confirmed.
A37: SETUP AND AUTOMATION
A38: Environment | B38: User-managed | C38: Install Python 3.11+, run the platform setup script, copy config templates, then run python -m system1 doctor.
A39: Automation | B39: Opt-in only | C39: Edit schedule.json and register it with the platform script. Moving the System1 folder requires unregistering and registering again.
A40: Concurrent editing | B40: Do not edit while System1 writes | C40: When making manual changes, pause or avoid the scheduled run. Excel-open and process locks prevent unsafe writes.
A42: RECOVERY
A43: Workbook repair prompt | B43: Choose No first | C43: Keep Excel closed, copy the latest backup from Code/runtime/backups, and run Validate Environment before retrying.
A44: DEFERRED_WORKBOOK_OPEN | B44: No data was changed | C44: Close Excel and run again.
A45: DEFERRED_ALREADY_RUNNING | B45: No second updater was started | C45: Wait for the current run to finish, then use View Last Run.
A46: FAIL or PAYWALL_BLOCKED | B46: Current valid file is preserved | C46: Use Human Operation Desktop for a corrected route or an authorised manual replacement.

Sheet Categories
A1: Categories and Controlled Values
A2: Program-generated controlled values. Do not edit this sheet directly; update approved configuration and regenerate.
A4: Classification dimension | Source family and identifier prefix
A5: Code | B5: Option value | C5: Definition | D5: Folder code
A6: PA | B6: Public authority | C6: Government, regulator or permitting authority | D6: A_Public_Authority
A7: SB | B7: Standards body | C7: Standards organisation such as NS, EN or ISO | D7: B_Standards_Body
A8: CS | B8: Certification scheme | C8: Certification scheme such as ASC or GLOBALG.A.P. | D8: C_Certification_Scheme
A9: MS | B9: Manufacturer / supplier | C9: Equipment manufacturer or supplier | D9: D_Manufacturer_Supplier
A10: PE | B10: Project / engineering | C10: Site, design or engineering source | D10: E_Project_Engineering
A11: CI | B11: Client / internal | C11: Client, contract or internal rule | D11: F_Client_Internal
A12: PC | B12: Pending classification | C12: Temporary category; cannot be directly included | D12: Z_Pending_Classification
A14: Classification dimension | Document type
A15: Code | B15: Option value | C15: Definition | D15: Notes
A16: LAW | B16: Law | C16: Primary legislation
A17: REG | B17: Regulation | C17: Secondary legislation or regulation
A18: PER | B18: Permit / authority decision | C18: Permit or site-specific administrative decision
A19: STD | B19: Technical standard | C19: NS, EN, ISO or industry technical standard
A20: SCH | B20: Scheme standard | C20: Primary certification scheme standard
A21: INT | B21: Interpretation document | C21: Interpretation manual or guidance
A22: AUD | B22: Audit / assessment document | C22: Audit manual, checklist or assessment tool
A23: MAN | B23: Equipment manual / OEM instruction | C23: Manufacturer installation, operation, maintenance or safety instruction
A24: ENG | B24: Design / engineering document | C24: Design basis, analysis or engineering report
A25: CON | B25: Internal policy / contract | C25: Client, contract or internal normative document
A26: OTH | B26: Other | C26: Use only when no controlled document type applies
A28: Classification dimension | Requirement role
A29: Code | B29: Option value | C29: Definition | D29: Notes
A30: PN | B30: Primary normative | C30: Directly creates requirements within the approved scope
A31: RN | B31: Referenced normative | C31: Applies through citation by law, contract or a primary source
A32: AN | B32: Asset-specific normative | C32: Creates requirements only for confirmed applicable equipment, model, asset or configuration
A33: GI | B33: Guidance / interpretation | C33: Helps interpretation but does not independently create requirements
A34: AT | B34: Audit / assessment tool | C34: Supports verification and should link to a primary source
A35: CE | B35: Context / evidence | C35: Provides facts or proof; only normative statements may become requirements
A36: DW | B36: Draft working material | C36: Working material that cannot be treated as formal authority
A38: Authoritative language
A39: Code | B39: Option value | C39: Definition | D39: Notes
A40: EN | B40: English | C40: English is authoritative | D40: Use the authoritative language first; among equivalent official versions the working preference is English, then Norwegian, then Other
A41: NO | B41: Norwegian | C41: Norwegian is authoritative
A42: OT | B42: Other | C42: Another language is authoritative; specify details in notes
A44: Jurisdiction
A45: Code | B45: Option value | C45: Definition | D45: Notes
...

Sheet Source Register
A1: PROGRAM-MANAGED | DO NOT EDIT DIRECTLY | P1: HUMAN-GOVERNED | CHANGES APPLIED FROM HUMAN OPERATION DESKTOP
A2: source_id | B2: snapshot_id | C2: stored_filename | D2: snapshot_status | E2: selection_status | F2: download_status | G2: last_attempt_at | H2: last_success_at | I2: content_change | J2: current_origin | K2: current_snapshot_date | L2: failure_stage | M2: failure_reason | N2: needs_human_action | O2: content_hash | P2: source_title | Q2: official_url | R2: retrieval_url | S2: folder_code | T2: file_format | U2: issuer | V2: jurisdiction | W2: authoritative_language | X2: version | Y2: effective_date | Z2: source_family | AA2: document_type | AB2: requirement_role | AC2: inclusion_rationale | AD2: authority_quality | AE2: scope_relevance | AF2: version_currency | AG2: traceability | AH2: access_permission | AI2: automation_readiness | AJ2: operator_selection_decision | AK2: manual_update_date | AL2: manual_updated_by | AM2: source_status | AN2: primary_source_id | AO2: notes | AP2: acquisition_channel | AQ2: provenance_status | AR2: update_model | AS2: applicability_reference
A3: PA001 | B3: PA001-001 | C3: PA001-001_Act_relating_to_aquaculture_Aquaculture_Act.html | D3: STORED | E3: =IF(A3="","",IF(OR(AJ3="EXCLUDE",COUNTIF(AD3:AH3,"LOW")>0),"EXCLUDE",IF(OR(AJ3<>"INCLUDE",F3<>"SUCCESS",D3<>"STORED",U3="",AP3="",AQ3="",AQ3="UNVERIFIED",AND(AP3="OFFICIAL_WEBSITE",Q3=""),AND(OR(AA3="Equipment manual / OEM instruction",AB3="Asset-specific normative"),OR(Z3<>"Manufacturer / supplier",AS3="",AC3=""))),"PENDING",IF(COUNTIF(AD3:AH3,"HIGH")=5,"INCLUDE","PENDING")))) | F3: SUCCESS | G3: 46262.531 | H3: 46262.531 | I3: INITIAL | J3: AUTO | K3: =IF(A3="","",IF(J3="AUTO",H3,IF(J3="MANUAL",AK3,""))) | L3: NONE | N3: =IF(A3="","",IF(COUNTIFS('Human Operation Desktop'!$A$3:$A$502,A3,'Human Operation Desktop'!$I$3:$I$502,"<>APPLIED",'Human Operation Desktop'!$I$3:$I$502,"<>REJECTED")>0,"YES","NO")) | O3: 8c9f2d952806c8dabc44294d197d55654284d98ff63683cae18633b9ab76a967 | P3: Act relating to aquaculture (Aquaculture Act) | Q3: https://lovdata.no/dokument/NL/lov/2005-06-17-79 | R3: https://lovdata.no/dokument/NL/lov/2005-06-17-79 | S3: A_Public_Authority | T3: html | U3: Norwegian Ministry of Trade, Industry and Fisheries | V3: Norway | W3: Norwegian | Z3: Public authority | AA3: Law | AB3: Primary normative | AC3: Official law issued by Norwegian Ministry of Trade, Industry and Fisheries; included because it may impose binding requirements on an in-scope aquaculture asset, activity, permit or certification. | AD3: HIGH | AE3: HIGH | AF3: HIGH | AG3: HIGH | AH3: HIGH | AI3: HIGH | AJ3: INCLUDE | AM3: CURRENT | AO3: Project-mentioned candidate. Client scope and applicability are not yet approved. | AP3: OFFICIAL_WEBSITE | AQ3: OFFICIAL_ORIGINAL | AR3: ROLLING
A4: PA002 | B4: PA002-001 | C4: PA002-001_Regulation_on_production_areas_for_sea-based_salmon_trout_and_rainbow_trout_aquaculture.html | D4: STORED | E4: =IF(A4="","",IF(OR(AJ4="EXCLUDE",COUNTIF(AD4:AH4,"LOW")>0),"EXCLUDE",IF(OR(AJ4<>"INCLUDE",F4<>"SUCCESS",D4<>"STORED",U4="",AP4="",AQ4="",AQ4="UNVERIFIED",AND(AP4="OFFICIAL_WEBSITE",Q4=""),AND(OR(AA4="Equipment manual / OEM instruction",AB4="Asset-specific normative"),OR(Z4<>"Manufacturer / supplier",AS4="",AC4=""))),"PENDING",IF(COUNTIF(AD4:AH4,"HIGH")=5,"INCLUDE","PENDING")))) | F4: SUCCESS | G4: 46262.531 | H4: 46262.531 | I4: INITIAL | J4: AUTO | K4: =IF(A4="","",IF(J4="AUTO",H4,IF(J4="MANUAL",AK4,""))) | L4: NONE | N4: =IF(A4="","",IF(COUNTIFS('Human Operation Desktop'!$A$3:$A$502,A4,'Human Operation Desktop'!$I$3:$I$502,"<>APPLIED",'Human Operation Desktop'!$I$3:$I$502,"<>REJECTED")>0,"YES","NO")) | O4: 19a632a343fe10fa8262a0ed8df8daa6d3e96e34ff686704da4c28e3671b2833 | P4: Regulation on production areas for sea-based salmon, trout and rainbow trout aquaculture | Q4: https://lovdata.no/dokument/SF/forskrift/2017-01-16-61 | R4: https://lovdata.no/dokument/SF/forskrift/2017-01-16-61 | S4: A_Public_Authority | T4: html | U4: Norwegian Ministry of Trade, Industry and Fisheries | V4: Norway | W4: Norwegian | Z4: Public authority | AA4: Regulation | AB4: Primary normative | AC4: Official regulation issued by Norwegian Ministry of Trade, Industry and Fisheries; included because it may impose binding requirements on an in-scope aquaculture asset, activity, permit or certification. | AD4: HIGH | AE4: HIGH | AF4: HIGH | AG4: HIGH | AH4: HIGH | AI4: HIGH | AJ4: INCLUDE | AM4: CURRENT | AO4: Project-mentioned candidate. Conditional on species, production area and sea-based operation. | AP4: OFFICIAL_WEBSITE | AQ4: OFFICIAL_ORIGINAL | AR4: ROLLING
A5: PA003 | B5: PA003-001 | C5: PA003-001_Regulation_on_the_operation_of_aquaculture_facilities_Aquaculture_Operations_Regulations.html | D5: STORED | E5: =IF(A5="","",IF(OR(AJ5="EXCLUDE",COUNTIF(AD5:AH5,"LOW")>0),"EXCLUDE",IF(OR(AJ5<>"INCLUDE",F5<>"SUCCESS",D5<>"STORED",U5="",AP5="",AQ5="",AQ5="UNVERIFIED",AND(AP5="OFFICIAL_WEBSITE",Q5=""),AND(OR(AA5="Equipment manual / OEM instruction",AB5="Asset-specific normative"),OR(Z5<>"Manufacturer / supplier",AS5="",AC5=""))),"PENDING",IF(COUNTIF(AD5:AH5,"HIGH")=5,"INCLUDE","PENDING")))) | F5: SUCCESS | G5: 46262.531 | H5: 46262.531 | I5: INITIAL | J5: AUTO | K5: =IF(A5="","",IF(J5="AUTO",H5,IF(J5="MANUAL",AK5,""))) | L5: NONE | N5: =IF(A5="","",IF(COUNTIFS('Human Operation Desktop'!$A$3:$A$502,A5,'Human Operation Desktop'!$I$3:$I$502,"<>APPLIED",'Human Operation Desktop'!$I$3:$I$502,"<>REJECTED")>0,"YES","NO")) | O5: 81650171c1177e709d49dfe6b19673e4d07f5425b3bbb5cbf8fef92e3421bbea | P5: Regulation on the operation of aquaculture facilities (Aquaculture Operations Regulations) | Q5: https://lovdata.no/dokument/SF/forskrift/2008-06-17-822 | R5: https://lovdata.no/dokument/SF/forskrift/2008-06-17-822 | S5: A_Public_Authority | T5: html | U5: Norwegian Government | V5: Norway | W5: Norwegian | Z5: Public authority | AA5: Regulation | AB5: Primary normative | AC5: Official regulation issued by Norwegian Government; included because it may impose binding requirements on an in-scope aquaculture asset, activity, permit or certification. | AD5: HIGH | AE5: HIGH | AF5: HIGH | AG5: HIGH | AH5: HIGH | AI5: HIGH | AJ5: INCLUDE | AM5: CURRENT | AO5: Project-mentioned candidate. Central operational source; scope confirmation is still required. | AP5: OFFICIAL_WEBSITE | AQ5: OFFICIAL_ORIGINAL | AR5: ROLLING
A6: PA004 | B6: PA004-001 | C6: PA004-001_NYTEK23_-_Regulation_on_technical_standards_for_aquaculture_facilities_for_fish_in_sea_lakes_and_watercourses.html | D6: STORED | E6: =IF(A6="","",IF(OR(AJ6="EXCLUDE",COUNTIF(AD6:AH6,"LOW")>0),"EXCLUDE",IF(OR(AJ6<>"INCLUDE",F6<>"SUCCESS",D6<>"STORED",U6="",AP6="",AQ6="",AQ6="UNVERIFIED",AND(AP6="OFFICIAL_WEBSITE",Q6=""),AND(OR(AA6="Equipment manual / OEM instruction",AB6="Asset-specific normative"),OR(Z6<>"Manufacturer / supplier",AS6="",AC6=""))),"PENDING",IF(COUNTIF(AD6:AH6,"HIGH")=5,"INCLUDE","PENDING")))) | F6: SUCCESS | G6: 46262.531 | H6: 46262.531 | I6: INITIAL | J6: AUTO | K6: =IF(A6="","",IF(J6="AUTO",H6,IF(J6="MANUAL",AK6,""))) | L6: NONE | N6: =IF(A6="","",IF(COUNTIFS('Human Operation Desktop'!$A$3:$A$502,A6,'Human Operation Desktop'!$I$3:$I$502,"<>APPLIED",'Human Operation Desktop'!$I$3:$I$502,"<>REJECTED")>0,"YES","NO")) | O6: a20988ddfe78bcf3d4ab87695f50f2c0f57f542fe77f2b1a66f94a81a993ce17 | P6: NYTEK23 - Regulation on technical standards for aquaculture facilities for fish in sea, lakes and watercourses | Q6: https://lovdata.no/dokument/SF/forskrift/2022-08-22-1484 | R6: https://lovdata.no/dokument/SF/forskrift/2022-08-22-1484 | S6: A_Public_Authority | T6: html | U6: Norwegian Ministry of Trade, Industry and Fisheries | V6: Norway | W6: Norwegian | Z6: Public authority | AA6: Regulation | AB6: Primary normative | AC6: Official regulation issued by Norwegian Ministry of Trade, Industry and Fisheries; included because it may impose binding requirements on an in-scope aquaculture asset, activity, permit or certification. | AD6: HIGH | AE6: HIGH | AF6: HIGH | AG6: HIGH | AH6: HIGH | AI6: HIGH | AJ6: INCLUDE | AM6: CURRENT | AO6: Project-mentioned candidate. Applies to relevant water-based fish facilities. | AP6: OFFICIAL_WEBSITE | AQ6: OFFICIAL_ORIGINAL | AR6: ROLLING
A7: PA005 | B7: PA005-001 | C7: PA005-001_Animal_Welfare_Act.html | D7: STORED | E7: =IF(A7="","",IF(OR(AJ7="EXCLUDE",COUNTIF(AD7:AH7,"LOW")>0),"EXCLUDE",IF(OR(AJ7<>"INCLUDE",F7<>"SUCCESS",D7<>"STORED",U7="",AP7="",AQ7="",AQ7="UNVERIFIED",AND(AP7="OFFICIAL_WEBSITE",Q7=""),AND(OR(AA7="Equipment manual / OEM instruction",AB7="Asset-specific normative"),OR(Z7<>"Manufacturer / supplier",AS7="",AC7=""))),"PENDING",IF(COUNTIF(AD7:AH7,"HIGH")=5,"INCLUDE","PENDING")))) | F7: SUCCESS | G7: 46262.531 | H7: 46262.531 | I7: INITIAL | J7: AUTO | K7: =IF(A7="","",IF(J7="AUTO",H7,IF(J7="MANUAL",AK7,""))) | L7: NONE | N7: =IF(A7="","",IF(COUNTIFS('Human Operation Desktop'!$A$3:$A$502,A7,'Human Operation Desktop'!$I$3:$I$502,"<>APPLIED",'Human Operation Desktop'!$I$3:$I$502,"<>REJECTED")>0,"YES","NO")) | O7: 121dce4cf5263302d47a467a612b437ffb1a6c660fb7454b6698101f16ea3808 | P7: Animal Welfare Act | Q7: https://lovdata.no/dokument/NL/lov/2009-06-19-97 | R7: https://lovdata.no/dokument/NL/lov/2009-06-19-97 | S7: A_Public_Authority | T7: html | U7: Norwegian Ministry of Agriculture and Food | V7: Norway | W7: Norwegian | Z7: Public authority | AA7: Law | AB7: Primary normative | AC7: Official law issued by Norwegian Ministry of Agriculture and Food; included because it may impose binding requirements on an in-scope aquaculture asset, activity, permit or certification. | AD7: HIGH | AE7: HIGH | AF7: HIGH | AG7: HIGH | AH7: HIGH | AI7: HIGH | AJ7: INCLUDE | AM7: CURRENT | AO7: Project-mentioned candidate covering fish and other aquatic animals. | AP7: OFFICIAL_WEBSITE | AQ7: OFFICIAL_ORIGINAL | AR7: ROLLING
A8: PA006 | B8: PA006-001 | C8: PA006-001_Organic_Production_and_Labelling_Regulations.html | D8: STORED | E8: =IF(A8="","",IF(OR(AJ8="EXCLUDE",COUNTIF(AD8:AH8,"LOW")>0),"EXCLUDE",IF(OR(AJ8<>"INCLUDE",F8<>"SUCCESS",D8<>"STORED",U8="",AP8="",AQ8="",AQ8="UNVERIFIED",AND(AP8="OFFICIAL_WEBSITE",Q8=""),AND(OR(AA8="Equipment manual / OEM instruction",AB8="Asset-specific normative"),OR(Z8<>"Manufacturer / supplier",AS8="",AC8=""))),"PENDING",IF(COUNTIF(AD8:AH8,"HIGH")=5,"INCLUDE","PENDING")))) | F8: SUCCESS | G8: 46262.531 | H8: 46262.531 | I8: INITIAL | J8: AUTO | K8: =IF(A8="","",IF(J8="AUTO",H8,IF(J8="MANUAL",AK8,""))) | L8: NONE | N8: =IF(A8="","",IF(COUNTIFS('Human Operation Desktop'!$A$3:$A$502,A8,'Human Operation Desktop'!$I$3:$I$502,"<>APPLIED",'Human Operation Desktop'!$I$3:$I$502,"<>REJECTED")>0,"YES","NO")) | O8: 18009ae503b2261b56c5c11ddde0a8a7400915f2d1b93894f3ea66085b7ec642 | P8: Organic Production and Labelling Regulations | Q8: https://lovdata.no/dokument/SF/forskrift/2022-06-11-1171 | R8: https://lovdata.no/dokument/SF/forskrift/2022-06-11-1171 | S8: A_Public_Authority | T8: html | U8: Norwegian Government | V8: Norway | W8: Norwegian | Z8: Public authority | AA8: Regulation | AB8: Primary normative | AC8: Official regulation issued by Norwegian Government; included because it may impose binding requirements on an in-scope aquaculture asset, activity, permit or certification. | AD8: HIGH | AE8: MEDIUM | AF8: HIGH | AG8: HIGH | AH8: HIGH | AI8: HIGH | AJ8: PENDING | AM8: CURRENT | AO8: Project-mentioned candidate. Include only for organic production or labelling scope. | AP8: OFFICIAL_WEBSITE | AQ8: OFFICIAL_ORIGINAL | AR8: ROLLING
A9: PA007 | B9: PA007-001 | C9: PA007-001_Pollution_Control_Act.html | D9: STORED | E9: =IF(A9="","",IF(OR(AJ9="EXCLUDE",COUNTIF(AD9:AH9,"LOW")>0),"EXCLUDE",IF(OR(AJ9<>"INCLUDE",F9<>"SUCCESS",D9<>"STORED",U9="",AP9="",AQ9="",AQ9="UNVERIFIED",AND(AP9="OFFICIAL_WEBSITE",Q9=""),AND(OR(AA9="Equipment manual / OEM instruction",AB9="Asset-specific normative"),OR(Z9<>"Manufacturer / supplier",AS9="",AC9=""))),"PENDING",IF(COUNTIF(AD9:AH9,"HIGH")=5,"INCLUDE","PENDING")))) | F9: SUCCESS | G9: 46262.531 | H9: 46262.531 | I9: INITIAL | J9: AUTO | K9: =IF(A9="","",IF(J9="AUTO",H9,IF(J9="MANUAL",AK9,""))) | L9: NONE | N9: =IF(A9="","",IF(COUNTIFS('Human Operation Desktop'!$A$3:$A$502,A9,'Human Operation Desktop'!$I$3:$I$502,"<>APPLIED",'Human Operation Desktop'!$I$3:$I$502,"<>REJECTED")>0,"YES","NO")) | O9: 6dbac9891bf38811447ed04c583140063ff23e0e1494e59f5ca0aa485b1e5901 | P9: Pollution Control Act | Q9: https://lovdata.no/dokument/NL/lov/1981-03-13-6 | R9: https://lovdata.no/dokument/NL/lov/1981-03-13-6 | S9: A_Public_Authority | T9: html | U9: Norwegian Ministry of Climate and Environment | V9: Norway | W9: Norwegian | Z9: Public authority | AA9: Law | AB9: Primary normative | AC9: Official law issued by Norwegian Ministry of Climate and Environment; included because it may impose binding requirements on an in-scope aquaculture asset, activity, permit or certification. | AD9: HIGH | AE9: HIGH | AF9: HIGH | AG9: HIGH | AH9: HIGH | AI9: HIGH | AJ9: INCLUDE | AM9: CURRENT | AO9: Project-mentioned candidate for emissions, waste and pollution permits. | AP9: OFFICIAL_WEBSITE | AQ9: OFFICIAL_ORIGINAL | AR9: ROLLING
A10: PA008 | B10: PA008-001 | C10: PA008-001_Water_Framework_Regulations.html | D10: STORED | E10: =IF(A10="","",IF(OR(AJ10="EXCLUDE",COUNTIF(AD10:AH10,"LOW")>0),"EXCLUDE",IF(OR(AJ10<>"INCLUDE",F10<>"SUCCESS",D10<>"STORED",U10="",AP10="",AQ10="",AQ10="UNVERIFIED",AND(AP10="OFFICIAL_WEBSITE",Q10=""),AND(OR(AA10="Equipment manual / OEM instruction",AB10="Asset-specific normative"),OR(Z10<>"Manufacturer / supplier",AS10="",AC10=""))),"PENDING",IF(COUNTIF(AD10:AH10,"HIGH")=5,"INCLUDE","PENDING")))) | F10: SUCCESS | G10: 46262.531 | H10: 46262.531 | I10: INITIAL | J10: AUTO | K10: =IF(A10="","",IF(J10="AUTO",H10,IF(J10="MANUAL",AK10,""))) | L10: NONE | N10: =IF(A10="","",IF(COUNTIFS('Human Operation Desktop'!$A$3:$A$502,A10,'Human Operation Desktop'!$I$3:$I$502,"<>APPLIED",'Human Operation Desktop'!$I$3:$I$502,"<>REJECTED")>0,"YES","NO")) | O10: bc9d9f926fe9f5ba2ee6df81938c45b7f4a20579ab7f7a149a5e9d1432169da2 | P10: Water Framework Regulations | Q10: https://lovdata.no/dokument/SF/forskrift/2006-12-15-1446 | R10: https://lovdata.no/dokument/SF/forskrift/2006-12-15-1446 | S10: A_Public_Authority | T10: html | U10: Norwegian Government | V10: Norway | W10: Norwegian | Z10: Public authority | AA10: Regulation | AB10: Referenced normative | AC10: Official referenced source from Norwegian Government; included because an applicable law, permit or certification scheme may make its provisions binding within the approved scope. | AD10: HIGH | AE10: MEDIUM | AF10: HIGH | AG10: HIGH | AH10: HIGH | AI10: HIGH | AJ10: PENDING | AM10: CURRENT | AO10: Project-mentioned candidate. Relevance depends on recipient and water-body assessment. | AP10: OFFICIAL_WEBSITE | AQ10: OFFICIAL_ORIGINAL | AR10: ROLLING
A11: PA009 | B11: PA009-001 | C11: PA009-001_Product_Control_Act.html | D11: STORED | E11: =IF(A11="","",IF(OR(AJ11="EXCLUDE",COUNTIF(AD11:AH11,"LOW")>0),"EXCLUDE",IF(OR(AJ11<>"INCLUDE",F11<>"SUCCESS",D11<>"STORED",U11="",AP11="",AQ11="",AQ11="UNVERIFIED",AND(AP11="OFFICIAL_WEBSITE",Q11=""),AND(OR(AA11="Equipment manual / OEM instruction",AB11="Asset-specific normative"),OR(Z11<>"Manufacturer / supplier",AS11="",AC11=""))),"PENDING",IF(COUNTIF(AD11:AH11,"HIGH")=5,"INCLUDE","PENDING")))) | F11: SUCCESS | G11: 46262.531 | H11: 46262.531 | I11: INITIAL | J11: AUTO | K11: =IF(A11="","",IF(J11="AUTO",H11,IF(J11="MANUAL",AK11,""))) | L11: NONE | N11: =IF(A11="","",IF(COUNTIFS('Human Operation Desktop'!$A$3:$A$502,A11,'Human Operation Desktop'!$I$3:$I$502,"<>APPLIED",'Human Operation Desktop'!$I$3:$I$502,"<>REJECTED")>0,"YES","NO")) | O11: 3805399145febb193e5e92fe37c364f9d2e0c87c260acc495f284639e92641a2 | P11: Product Control Act | Q11: https://lovdata.no/dokument/NL/lov/1976-06-11-79 | R11: https://lovdata.no/dokument/NL/lov/1976-06-11-79 | S11: A_Public_Authority | T11: html | U11: Norwegian Ministry of Climate and Environment | V11: Norway | W11: Norwegian | Z11: Public authority | AA11: Law | AB11: Primary normative | AC11: Official law issued by Norwegian Ministry of Climate and Environment; included because it may impose binding requirements on an in-scope aquaculture asset, activity, permit or certification. | AD11: HIGH | AE11: HIGH | AF11: HIGH | AG11: HIGH | AH11: HIGH | AI11: HIGH | AJ11: INCLUDE | AM11: CURRENT | AO11: Project-mentioned candidate, including substitution duties for harmful products. | AP11: OFFICIAL_WEBSITE | AQ11: OFFICIAL_ORIGINAL | AR11: ROLLING
A12: PA010 | B12: PA010-001 | C12: PA010-001_Regulation_EU_2016_429_on_transmissible_animal_diseases_Animal_Health_Law.html | D12: STORED | E12: =IF(A12="","",IF(OR(AJ12="EXCLUDE",COUNTIF(AD12:AH12,"LOW")>0),"EXCLUDE",IF(OR(AJ12<>"INCLUDE",F12<>"SUCCESS",D12<>"STORED",U12="",AP12="",AQ12="",AQ12="UNVERIFIED",AND(AP12="OFFICIAL_WEBSITE",Q12=""),AND(OR(AA12="Equipment manual / OEM instruction",AB12="Asset-specific normative"),OR(Z12<>"Manufacturer / supplier",AS12="",AC12=""))),"PENDING",IF(COUNTIF(AD12:AH12,"HIGH")=5,"INCLUDE","PENDING")))) | F12: SUCCESS | G12: 46265.447 | H12: 46265.447 | I12: INITIAL | J12: AUTO | K12: =IF(A12="","",IF(J12="AUTO",H12,IF(J12="MANUAL",AK12,""))) | L12: NONE | N12: =IF(A12="","",IF(COUNTIFS('Human Operation Desktop'!$A$3:$A$502,A12,'Human Operation Desktop'!$I$3:$I$502,"<>APPLIED",'Human Operation Desktop'!$I$3:$I$502,"<>REJECTED")>0,"YES","NO")) | O12: 3ac51613dbdfb998b2d2c68e2df564b8a19c7d398d34d52f0228e6c10c30f8ed | P12: Regulation (EU) 2016/429 on transmissible animal diseases (Animal Health Law) | Q12: https://eur-lex.europa.eu/legal-content/EN/TXT/?uri=CELEX:32016R0429 | R12: https://publications.europa.eu/resource/oj/JOL_2016_084_R_0001.ENG | S12: A_Public_Authority | T12: html | U12: European Parliament and Council of the European Union | V12: EU / EEA | W12: English | Z12: Public authority | AA12: Regulation | AB12: Referenced normative | AC12: Official referenced source from European Parliament and Council of the European Union; included because an applicable law, permit or certification scheme may make its provisions binding within the approved scope. | AD12: HIGH | AE12: MEDIUM | AF12: HIGH | AG12: HIGH | AH12: HIGH | AI12: HIGH | AJ12: PENDING | AK12: 46265 | AL12: Jay | AM12: CURRENT | AO12: Human review 2026-08-31: the prior language-neutral ELI URL did not select English. The official URL now uses the explicit English document view. The retrieval URL now uses the official English XHTML manifestation from the Publications Office for deterministic content negotiation. EEA/Norwegian applicability still requires separate confirmation. | AP12: OFFICIAL_WEBSITE | AQ12: OFFICIAL_ORIGINAL | AR12: ROLLING
A13: PA011 | B13: PA011-001 | C13: PA011-001_Working_Environment_Act.html | D13: STORED | E13: =IF(A13="","",IF(OR(AJ13="EXCLUDE",COUNTIF(AD13:AH13,"LOW")>0),"EXCLUDE",IF(OR(AJ13<>"INCLUDE",F13<>"SUCCESS",D13<>"STORED",U13="",AP13="",AQ13="",AQ13="UNVERIFIED",AND(AP13="OFFICIAL_WEBSITE",Q13=""),AND(OR(AA13="Equipment manual / OEM instruction",AB13="Asset-specific normative"),OR(Z13<>"Manufacturer / supplier",AS13="",AC13=""))),"PENDING",IF(COUNTIF(AD13:AH13,"HIGH")=5,"INCLUDE","PENDING")))) | F13: SUCCESS | G13: 46262.531 | H13: 46262.531 | I13: INITIAL | J13: AUTO | K13: =IF(A13="","",IF(J13="AUTO",H13,IF(J13="MANUAL",AK13,""))) | L13: NONE | N13: =IF(A13="","",IF(COUNTIFS('Human Operation Desktop'!$A$3:$A$502,A13,'Human Operation Desktop'!$I$3:$I$502,"<>APPLIED",'Human Operation Desktop'!$I$3:$I$502,"<>REJECTED")>0,"YES","NO")) | O13: 96cec52793e643ff1daf51254216f36e1ac4b2216e80dea9f09161708d0a9170 | P13: Working Environment Act | Q13: https://lovdata.no/dokument/NL/lov/2005-06-17-62 | R13: https://lovdata.no/dokument/NL/lov/2005-06-17-62 | S13: A_Public_Authority | T13: html | U13: Norwegian Ministry of Labour and Social Inclusion | V13: Norway | W13: Norwegian | Z13: Public authority | AA13: Law | AB13: Primary normative | AC13: Official law issued by Norwegian Ministry of Labour and Social Inclusion; included because it may impose binding requirements on an in-scope aquaculture asset, activity, permit or certification. | AD13: HIGH | AE13: HIGH | AF13: HIGH | AG13: HIGH | AH13: HIGH | AI13: HIGH | AJ13: INCLUDE | AM13: CURRENT | AO13: Project-mentioned candidate for worker health, safety and training. | AP13: OFFICIAL_WEBSITE | AQ13: OFFICIAL_ORIGINAL | AR13: ROLLING
A14: PA012 | B14: PA012-001 | C14: PA012-001_Regulations_concerning_the_performance_of_work_psychosocial_working_environment_use_of_work_equipment_and_related_techni.html | D14: STORED | E14: =IF(A14="","",IF(OR(AJ14="EXCLUDE",COUNTIF(AD14:AH14,"LOW")>0),"EXCLUDE",IF(OR(AJ14<>"INCLUDE",F14<>"SUCCESS",D14<>"STORED",U14="",AP14="",AQ14="",AQ14="UNVERIFIED",AND(AP14="OFFICIAL_WEBSITE",Q14=""),AND(OR(AA14="Equipment manual / OEM instruction",AB14="Asset-specific normative"),OR(Z14<>"Manufacturer / supplier",AS14="",AC14=""))),"PENDING",IF(COUNTIF(AD14:AH14,"HIGH")=5,"INCLUDE","PENDING")))) | F14: SUCCESS | G14: 46262.531 | H14: 46262.531 | I14: INITIAL | J14: AUTO | K14: =IF(A14="","",IF(J14="AUTO",H14,IF(J14="MANUAL",AK14,""))) | L14: NONE | N14: =IF(A14="","",IF(COUNTIFS('Human Operation Desktop'!$A$3:$A$502,A14,'Human Operation Desktop'!$I$3:$I$502,"<>APPLIED",'Human Operation Desktop'!$I$3:$I$502,"<>REJECTED")>0,"YES","NO")) | O14: 15cc7d1de65ea3277121031dd0c7e4d7b44ea7950fdfbd38df7d402255860e68 | P14: Regulations concerning the performance of work, psychosocial working environment, use of work equipment and related technical requirements | Q14: https://lovdata.no/dokument/SF/forskrift/2011-12-06-1357 | R14: https://lovdata.no/dokument/SF/forskrift/2011-12-06-1357 | S14: A_Public_Authority | T14: html | U14: Norwegian Ministry of Labour and Social Inclusion | V14: Norway | W14: Norwegian | Z14: Public authority | AA14: Regulation | AB14: Primary normative | AC14: Official regulation issued by Norwegian Ministry of Labour and Social Inclusion; included because it may impose binding requirements on an in-scope aquaculture asset, activity, permit or certification. | AD14: HIGH | AE14: HIGH | AF14: HIGH | AG14: HIGH | AH14: HIGH | AI14: HIGH | AJ14: INCLUDE | AM14: CURRENT | AO14: Project-mentioned candidate. Applicability depends on work activities and equipment. | AP14: OFFICIAL_WEBSITE | AQ14: OFFICIAL_ORIGINAL | AR14: ROLLING
A15: PA013 | B15: PA013-001 | C15: PA013-001_Food_Act.html | D15: STORED | E15: =IF(A15="","",IF(OR(AJ15="EXCLUDE",COUNTIF(AD15:AH15,"LOW")>0),"EXCLUDE",IF(OR(AJ15<>"INCLUDE",F15<>"SUCCESS",D15<>"STORED",U15="",AP15="",AQ15="",AQ15="UNVERIFIED",AND(AP15="OFFICIAL_WEBSITE",Q15=""),AND(OR(AA15="Equipment manual / OEM instruction",AB15="Asset-specific normative"),OR(Z15<>"Manufacturer / supplier",AS15="",AC15=""))),"PENDING",IF(COUNTIF(AD15:AH15,"HIGH")=5,"INCLUDE","PENDING")))) | F15: SUCCESS | G15: 46262.531 | H15: 46262.531 | I15: INITIAL | J15: AUTO | K15: =IF(A15="","",IF(J15="AUTO",H15,IF(J15="MANUAL",AK15,""))) | L15: NONE | N15: =IF(A15="","",IF(COUNTIFS('Human Operation Desktop'!$A$3:$A$502,A15,'Human Operation Desktop'!$I$3:$I$502,"<>APPLIED",'Human Operation Desktop'!$I$3:$I$502,"<>REJECTED")>0,"YES","NO")) | O15: fffe78cee31f4f34218728d0e8d8919b5fe5ccae40e8f41a067757370372d8db | P15: Food Act | Q15: https://lovdata.no/dokument/NL/lov/2003-12-19-124 | R15: https://lovdata.no/dokument/NL/lov/2003-12-19-124 | S15: A_Public_Authority | T15: html | U15: Norwegian Government | V15: Norway | W15: Norwegian | Z15: Public authority | AA15: Law | AB15: Primary normative | AC15: Official law issued by Norwegian Government; included because it may impose binding requirements on an in-scope aquaculture asset, activity, permit or certification. | AD15: HIGH | AE15: HIGH | AF15: HIGH | AG15: HIGH | AH15: HIGH | AI15: HIGH | AJ15: INCLUDE | AM15: CURRENT | AO15: Official expansion from Fiskeridirektoratet risk-management sources; scope confirmation required. | AP15: OFFICIAL_WEBSITE | AQ15: OFFICIAL_ORIGINAL | AR15: ROLLING
A16: PA014 | B16: PA014-001 | C16: PA014-001_Animal_Health_Personnel_Act.html | D16: STORED | E16: =IF(A16="","",IF(OR(AJ16="EXCLUDE",COUNTIF(AD16:AH16,"LOW")>0),"EXCLUDE",IF(OR(AJ16<>"INCLUDE",F16<>"SUCCESS",D16<>"STORED",U16="",AP16="",AQ16="",AQ16="UNVERIFIED",AND(AP16="OFFICIAL_WEBSITE",Q16=""),AND(OR(AA16="Equipment manual / OEM instruction",AB16="Asset-specific normative"),OR(Z16<>"Manufacturer / supplier",AS16="",AC16=""))),"PENDING",IF(COUNTIF(AD16:AH16,"HIGH")=5,"INCLUDE","PENDING")))) | F16: SUCCESS | G16: 46262.531 | H16: 46262.531 | I16: INITIAL | J16: AUTO | K16: =IF(A16="","",IF(J16="AUTO",H16,IF(J16="MANUAL",AK16,""))) | L16: NONE | N16: =IF(A16="","",IF(COUNTIFS('Human Operation Desktop'!$A$3:$A$502,A16,'Human Operation Desktop'!$I$3:$I$502,"<>APPLIED",'Human Operation Desktop'!$I$3:$I$502,"<>REJECTED")>0,"YES","NO")) | O16: d1f92d2c418243c85675fe93401a76b489b88306833b3478073fa844aa83b30b | P16: Animal Health Personnel Act | Q16: https://lovdata.no/dokument/NL/lov/2001-06-15-75 | R16: https://lovdata.no/dokument/NL/lov/2001-06-15-75 | S16: A_Public_Authority | T16: html | U16: Norwegian Ministry of Agriculture and Food | V16: Norway | W16: Norwegian | Z16: Public authority | AA16: Law | AB16: Primary normative | AC16: Official law issued by Norwegian Ministry of Agriculture and Food; included because it may impose binding requirements on an in-scope aquaculture asset, activity, permit or certification. | AD16: HIGH | AE16: MEDIUM | AF16: HIGH | AG16: HIGH | AH16: HIGH | AI16: HIGH | AJ16: PENDING | AM16: CURRENT | AO16: Official expansion. Relevant where veterinarians or aquatic animal health personnel perform regulated tasks. | AP16: OFFICIAL_WEBSITE | AQ16: OFFICIAL_ORIGINAL | AR16: ROLLING
A17: PA015 | B17: PA015-001 | C17: PA015-001_Regulation_on_control_of_salmon_lice_in_aquaculture_facilities.html | D17: STORED | E17: =IF(A17="","",IF(OR(AJ17="EXCLUDE",COUNTIF(AD17:AH17,"LOW")>0),"EXCLUDE",IF(OR(AJ17<>"INCLUDE",F17<>"SUCCESS",D17<>"STORED",U17="",AP17="",AQ17="",AQ17="UNVERIFIED",AND(AP17="OFFICIAL_WEBSITE",Q17=""),AND(OR(AA17="Equipment manual / OEM instruction",AB17="Asset-specific normative"),OR(Z17<>"Manufacturer / supplier",AS17="",AC17=""))),"PENDING",IF(COUNTIF(AD17:AH17,"HIGH")=5,"INCLUDE","PENDING")))) | F17: SUCCESS | G17: 46262.531 | H17: 46262.531 | I17: INITIAL | J17: AUTO | K17: =IF(A17="","",IF(J17="AUTO",H17,IF(J17="MANUAL",AK17,""))) | L17: NONE | N17: =IF(A17="","",IF(COUNTIFS('Human Operation Desktop'!$A$3:$A$502,A17,'Human Operation Desktop'!$I$3:$I$502,"<>APPLIED",'Human Operation Desktop'!$I$3:$I$502,"<>REJECTED")>0,"YES","NO")) | O17: 9334a78a021971411e5c8826a2bb16aab1db707d778f6249c9a36b0afc90a4a1 | P17: Regulation on control of salmon lice in aquaculture facilities | Q17: https://lovdata.no/dokument/SF/forskrift/2012-12-05-1140 | R17: https://lovdata.no/dokument/SF/forskrift/2012-12-05-1140 | S17: A_Public_Authority | T17: html | U17: Norwegian Ministry of Trade, Industry and Fisheries | V17: Norway | W17: Norwegian | Z17: Public authority | AA17: Regulation | AB17: Primary normative | AC17: Official regulation issued by Norwegian Ministry of Trade, Industry and Fisheries; included because it may impose binding requirements on an in-scope aquaculture asset, activity, permit or certification. | AD17: HIGH | AE17: HIGH | AF17: HIGH | AG17: HIGH | AH17: HIGH | AI17: HIGH | AJ17: INCLUDE | AM17: CURRENT | AO17: Official expansion from Fiskeridirektoratet risk-management sources; species and operation scope must be confirmed. | AP17: OFFICIAL_WEBSITE | AQ17: OFFICIAL_ORIGINAL | AR17: ROLLING
A18: PA016 | B18: PA016-001 | C18: PA016-001_Regulation_on_internal_control_to_comply_with_aquaculture_legislation_IK-Aquaculture.html | D18: STORED | E18: =IF(A18="","",IF(OR(AJ18="EXCLUDE",COUNTIF(AD18:AH18,"LOW")>0),"EXCLUDE",IF(OR(AJ18<>"INCLUDE",F18<>"SUCCESS",D18<>"STORED",U18="",AP18="",AQ18="",AQ18="UNVERIFIED",AND(AP18="OFFICIAL_WEBSITE",Q18=""),AND(OR(AA18="Equipment manual / OEM instruction",AB18="Asset-specific normative"),OR(Z18<>"Manufacturer / supplier",AS18="",AC18=""))),"PENDING",IF(COUNTIF(AD18:AH18,"HIGH")=5,"INCLUDE","PENDING")))) | F18: SUCCESS | G18: 46262.531 | H18: 46262.531 | I18: INITIAL | J18: AUTO | K18: =IF(A18="","",IF(J18="AUTO",H18,IF(J18="MANUAL",AK18,""))) | L18: NONE | N18: =IF(A18="","",IF(COUNTIFS('Human Operation Desktop'!$A$3:$A$502,A18,'Human Operation Desktop'!$I$3:$I$502,"<>APPLIED",'Human Operation Desktop'!$I$3:$I$502,"<>REJECTED")>0,"YES","NO")) | O18: a8a24e5e32dfc061868654b4e1fa2c6925b6333aa34a41c952cc66de9710977b | P18: Regulation on internal control to comply with aquaculture legislation (IK-Aquaculture) | Q18: https://lovdata.no/dokument/SF/forskrift/2004-03-19-537 | R18: https://lovdata.no/dokument/SF/forskrift/2004-03-19-537 | S18: A_Public_Authority | T18: html | U18: Norwegian Government | V18: Norway | W18: Norwegian | Z18: Public authority | AA18: Regulation | AB18: Primary normative | AC18: Official regulation issued by Norwegian Government; included because it may impose binding requirements on an in-scope aquaculture asset, activity, permit or certification. | AD18: HIGH | AE18: HIGH | AF18: HIGH | AG18: HIGH | AH18: HIGH | AI18: HIGH | AJ18: INCLUDE | AM18: CURRENT | AO18: Official expansion. Core management-system candidate for Norwegian aquaculture operations. | AP18: OFFICIAL_WEBSITE | AQ18: OFFICIAL_ORIGINAL | AR18: ROLLING
A19: PA017 | B19: PA017-001 | C19: PA017-001_Internal_Control_Regulations.html | D19: STORED | E19: =IF(A19="","",IF(OR(AJ19="EXCLUDE",COUNTIF(AD19:AH19,"LOW")>0),"EXCLUDE",IF(OR(AJ19<>"INCLUDE",F19<>"SUCCESS",D19<>"STORED",U19="",AP19="",AQ19="",AQ19="UNVERIFIED",AND(AP19="OFFICIAL_WEBSITE",Q19=""),AND(OR(AA19="Equipment manual / OEM instruction",AB19="Asset-specific normative"),OR(Z19<>"Manufacturer / supplier",AS19="",AC19=""))),"PENDING",IF(COUNTIF(AD19:AH19,"HIGH")=5,"INCLUDE","PENDING")))) | F19: SUCCESS | G19: 46262.531 | H19: 46262.531 | I19: INITIAL | J19: AUTO | K19: =IF(A19="","",IF(J19="AUTO",H19,IF(J19="MANUAL",AK19,""))) | L19: NONE | N19: =IF(A19="","",IF(COUNTIFS('Human Operation Desktop'!$A$3:$A$502,A19,'Human Operation Desktop'!$I$3:$I$502,"<>APPLIED",'Human Operation Desktop'!$I$3:$I$502,"<>REJECTED")>0,"YES","NO")) | O19: 7f640e3626fbd2d3aa9e6f8f0fad328170f26e4a73a9f59fd20ffe74f400b546 | P19: Internal Control Regulations | Q19: https://lovdata.no/dokument/SF/forskrift/1996-12-06-1127 | R19: https://lovdata.no/dokument/SF/forskrift/1996-12-06-1127 | S19: A_Public_Authority | T19: html | U19: Norwegian Government | V19: Norway | W19: Norwegian | Z19: Public authority | AA19: Regulation | AB19: Primary normative | AC19: Official regulation issued by Norwegian Government; included because it may impose binding requirements on an in-scope aquaculture asset, activity, permit or certification. | AD19: HIGH | AE19: HIGH | AF19: HIGH | AG19: HIGH | AH19: HIGH | AI19: HIGH | AJ19: INCLUDE | AM19: CURRENT | AO19: Official expansion. Cross-sector HSE internal-control source; overlap with IK-Aquaculture requires later mapping. | AP19: OFFICIAL_WEBSITE | AQ19: OFFICIAL_ORIGINAL | AR19: ROLLING
A20: PA018 | B20: PA018-001 | C20: PA018-001_Ship_Safety_and_Security_Act.html | D20: STORED | E20: =IF(A20="","",IF(OR(AJ20="EXCLUDE",COUNTIF(AD20:AH20,"LOW")>0),"EXCLUDE",IF(OR(AJ20<>"INCLUDE",F20<>"SUCCESS",D20<>"STORED",U20="",AP20="",AQ20="",AQ20="UNVERIFIED",AND(AP20="OFFICIAL_WEBSITE",Q20=""),AND(OR(AA20="Equipment manual / OEM instruction",AB20="Asset-specific normative"),OR(Z20<>"Manufacturer / supplier",AS20="",AC20=""))),"PENDING",IF(COUNTIF(AD20:AH20,"HIGH")=5,"INCLUDE","PENDING")))) | F20: SUCCESS | G20: 46262.531 | H20: 46262.531 | I20: INITIAL | J20: AUTO | K20: =IF(A20="","",IF(J20="AUTO",H20,IF(J20="MANUAL",AK20,""))) | L20: NONE | N20: =IF(A20="","",IF(COUNTIFS('Human Operation Desktop'!$A$3:$A$502,A20,'Human Operation Desktop'!$I$3:$I$502,"<>APPLIED",'Human Operation Desktop'!$I$3:$I$502,"<>REJECTED")>0,"YES","NO")) | O20: 535ce0ef3c8d36ecc15baf5c64f069fdb5f62dd72579d24e1c6157acc8cdf009 | P20: Ship Safety and Security Act | Q20: https://lovdata.no/dokument/NL/lov/2007-02-16-9 | R20: https://lovdata.no/dokument/NL/lov/2007-02-16-9 | S20: A_Public_Authority | T20: html | U20: Norwegian Government | V20: Norway | W20: Norwegian | Z20: Public authority | AA20: Law | AB20: Primary normative | AC20: Official law issued by Norwegian Government; included because it may impose binding requirements on an in-scope aquaculture asset, activity, permit or certification. | AD20: HIGH | AE20: MEDIUM | AF20: HIGH | AG20: HIGH | AH20: HIGH | AI20: HIGH | AJ20: PENDING | AM20: CURRENT | AO20: Official expansion. Conditional on vessels and maritime operations within client scope. | AP20: OFFICIAL_WEBSITE | AQ20: OFFICIAL_ORIGINAL | AR20: ROLLING
A21: PA019 | B21: PA019-001 | C21: PA019-001_Regulation_on_transport_of_aquaculture_animals.html | D21: STORED | E21: =IF(A21="","",IF(OR(AJ21="EXCLUDE",COUNTIF(AD21:AH21,"LOW")>0),"EXCLUDE",IF(OR(AJ21<>"INCLUDE",F21<>"SUCCESS",D21<>"STORED",U21="",AP21="",AQ21="",AQ21="UNVERIFIED",AND(AP21="OFFICIAL_WEBSITE",Q21=""),AND(OR(AA21="Equipment manual / OEM instruction",AB21="Asset-specific normative"),OR(Z21<>"Manufacturer / supplier",AS21="",AC21=""))),"PENDING",IF(COUNTIF(AD21:AH21,"HIGH")=5,"INCLUDE","PENDING")))) | F21: SUCCESS | G21: 46262.531 | H21: 46262.531 | I21: INITIAL | J21: AUTO | K21: =IF(A21="","",IF(J21="AUTO",H21,IF(J21="MANUAL",AK21,""))) | L21: NONE | N21: =IF(A21="","",IF(COUNTIFS('Human Operation Desktop'!$A$3:$A$502,A21,'Human Operation Desktop'!$I$3:$I$502,"<>APPLIED",'Human Operation Desktop'!$I$3:$I$502,"<>REJECTED")>0,"YES","NO")) | O21: c3a1a1d71bad6255d833abf37550f8ef1d79c996a82468a85fccbb7a474e6ded | P21: Regulation on transport of aquaculture animals | Q21: https://lovdata.no/dokument/SF/forskrift/2008-06-17-820 | R21: https://lovdata.no/dokument/SF/forskrift/2008-06-17-820 | S21: A_Public_Authority | T21: html | U21: Norwegian Government | V21: Norway | W21: Norwegian | Z21: Public authority | AA21: Regulation | AB21: Primary normative | AC21: Official regulation issued by Norwegian Government; included because it may impose binding requirements on an in-scope aquaculture asset, activity, permit or certification. | AD21: HIGH | AE21: MEDIUM | AF21: HIGH | AG21: HIGH | AH21: HIGH | AI21: HIGH | AJ21: PENDING | AM21: CURRENT | AO21: Official expansion from Mattilsynet. Conditional on live-animal transport activities. | AP21: OFFICIAL_WEBSITE | AQ21: OFFICIAL_ORIGINAL | AR21: ROLLING
A22: PA020 | B22: PA020-001 | C22: PA020-001_Regulation_on_slaughterhouses_and_processing_facilities_for_aquaculture_animals.html | D22: STORED | E22: =IF(A22="","",IF(OR(AJ22="EXCLUDE",COUNTIF(AD22:AH22,"LOW")>0),"EXCLUDE",IF(OR(AJ22<>"INCLUDE",F22<>"SUCCESS",D22<>"STORED",U22="",AP22="",AQ22="",AQ22="UNVERIFIED",AND(AP22="OFFICIAL_WEBSITE",Q22=""),AND(OR(AA22="Equipment manual / OEM instruction",AB22="Asset-specific normative"),OR(Z22<>"Manufacturer / supplier",AS22="",AC22=""))),"PENDING",IF(COUNTIF(AD22:AH22,"HIGH")=5,"INCLUDE","PENDING")))) | F22: SUCCESS | G22: 46262.531 | H22: 46262.531 | I22: INITIAL | J22: AUTO | K22: =IF(A22="","",IF(J22="AUTO",H22,IF(J22="MANUAL",AK22,""))) | L22: NONE | N22: =IF(A22="","",IF(COUNTIFS('Human Operation Desktop'!$A$3:$A$502,A22,'Human Operation Desktop'!$I$3:$I$502,"<>APPLIED",'Human Operation Desktop'!$I$3:$I$502,"<>REJECTED")>0,"YES","NO")) | O22: 660825e1fb0f6b15f9e8501319e334d7b67de1790c34645715f5b184d3d397cc | P22: Regulation on slaughterhouses and processing facilities for aquaculture animals | Q22: https://lovdata.no/dokument/SF/forskrift/2006-10-30-1250 | R22: https://lovdata.no/dokument/SF/forskrift/2006-10-30-1250 | S22: A_Public_Authority | T22: html | U22: Norwegian Ministry of Trade, Industry and Fisheries | V22: Norway | W22: Norwegian | Z22: Public authority | AA22: Regulation | AB22: Primary normative | AC22: Official regulation issued by Norwegian Ministry of Trade, Industry and Fisheries; included because it may impose binding requirements on an in-scope aquaculture asset, activity, permit or certification. | AD22: HIGH | AE22: MEDIUM | AF22: HIGH | AG22: HIGH | AH22: HIGH | AI22: HIGH | AJ22: PENDING | AM22: CURRENT | AO22: Official expansion from Mattilsynet. Include only when slaughter or processing is in scope. | AP22: OFFICIAL_WEBSITE | AQ22: OFFICIAL_ORIGINAL | AR22: ROLLING
A23: PA021 | B23: PA021-001 | C23: PA021-001_Regulation_on_permits_for_aquaculture_of_salmon_trout_and_rainbow_trout_Salmon_Allocation_Regulations.html | D23: STORED | E23: =IF(A23="","",IF(OR(AJ23="EXCLUDE",COUNTIF(AD23:AH23,"LOW")>0),"EXCLUDE",IF(OR(AJ23<>"INCLUDE",F23<>"SUCCESS",D23<>"STORED",U23="",AP23="",AQ23="",AQ23="UNVERIFIED",AND(AP23="OFFICIAL_WEBSITE",Q23=""),AND(OR(AA23="Equipment manual / OEM instruction",AB23="Asset-specific normative"),OR(Z23<>"Manufacturer / supplier",AS23="",AC23=""))),"PENDING",IF(COUNTIF(AD23:AH23,"HIGH")=5,"INCLUDE","PENDING")))) | F23: SUCCESS | G23: 46262.531 | H23: 46262.531 | I23: INITIAL | J23: AUTO | K23: =IF(A23="","",IF(J23="AUTO",H23,IF(J23="MANUAL",AK23,""))) | L23: NONE | N23: =IF(A23="","",IF(COUNTIFS('Human Operation Desktop'!$A$3:$A$502,A23,'Human Operation Desktop'!$I$3:$I$502,"<>APPLIED",'Human Operation Desktop'!$I$3:$I$502,"<>REJECTED")>0,"YES","NO")) | O23: 7ad31127a98909210f86c2df281141adc3218206d348c07c01be4a00c540964d | P23: Regulation on permits for aquaculture of salmon, trout and rainbow trout (Salmon Allocation Regulations) | Q23: https://lovdata.no/dokument/SF/forskrift/2022-11-07-1929 | R23: https://lovdata.no/dokument/SF/forskrift/2022-11-07-1929 | S23: A_Public_Authority | T23: html | U23: Norwegian Ministry of Trade, Industry and Fisheries | V23: Norway | W23: Norwegian | Z23: Public authority | AA23: Regulation | AB23: Primary normative | AC23: Official regulation issued by Norwegian Ministry of Trade, Industry and Fisheries; included because it may impose binding requirements on an in-scope aquaculture asset, activity, permit or certification. | AD23: HIGH | AE23: MEDIUM | AF23: HIGH | AG23: HIGH | AH23: HIGH | AI23: HIGH | AJ23: PENDING | AM23: CURRENT | AO23: Official expansion from Fiskeridirektoratet's aquaculture regulation index; conditional on species and permit type. | AP23: OFFICIAL_WEBSITE | AQ23: OFFICIAL_ORIGINAL | AR23: ROLLING
A24: PA022 | B24: PA022-001 | C24: PA022-001_Regulation_on_technical_standards_for_land-based_aquaculture_facilities_for_fish.html | D24: STORED | E24: =IF(A24="","",IF(OR(AJ24="EXCLUDE",COUNTIF(AD24:AH24,"LOW")>0),"EXCLUDE",IF(OR(AJ24<>"INCLUDE",F24<>"SUCCESS",D24<>"STORED",U24="",AP24="",AQ24="",AQ24="UNVERIFIED",AND(AP24="OFFICIAL_WEBSITE",Q24=""),AND(OR(AA24="Equipment manual / OEM instruction",AB24="Asset-specific normative"),OR(Z24<>"Manufacturer / supplier",AS24="",AC24=""))),"PENDING",IF(COUNTIF(AD24:AH24,"HIGH")=5,"INCLUDE","PENDING")))) | F24: SUCCESS | G24: 46262.531 | H24: 46262.531 | I24: INITIAL | J24: AUTO | K24: =IF(A24="","",IF(J24="AUTO",H24,IF(J24="MANUAL",AK24,""))) | L24: NONE | N24: =IF(A24="","",IF(COUNTIFS('Human Operation Desktop'!$A$3:$A$502,A24,'Human Operation Desktop'!$I$3:$I$502,"<>APPLIED",'Human Operation Desktop'!$I$3:$I$502,"<>REJECTED")>0,"YES","NO")) | O24: 2ab1905061a870af1b05ec9e1c8536e90157d00d70217305629365e4986c1918 | P24: Regulation on technical standards for land-based aquaculture facilities for fish | Q24: https://lovdata.no/dokument/SF/forskrift/2017-06-19-941 | R24: https://lovdata.no/dokument/SF/forskrift/2017-06-19-941 | S24: A_Public_Authority | T24: html | U24: Norwegian Ministry of Trade, Industry and Fisheries | V24: Norway | W24: Norwegian | Z24: Public authority | AA24: Regulation | AB24: Primary normative | AC24: Official regulation issued by Norwegian Ministry of Trade, Industry and Fisheries; included because it may impose binding requirements on an in-scope aquaculture asset, activity, permit or certification. | AD24: HIGH | AE24: MEDIUM | AF24: HIGH | AG24: HIGH | AH24: HIGH | AI24: HIGH | AJ24: PENDING | AM24: CURRENT | AO24: Official expansion. Include only for land-based facilities. | AP24: OFFICIAL_WEBSITE | AQ24: OFFICIAL_ORIGINAL | AR24: ROLLING
A25: PA023 | B25: PA023-001 | C25: PA023-001_Nature_Diversity_Act.html | D25: STORED | E25: =IF(A25="","",IF(OR(AJ25="EXCLUDE",COUNTIF(AD25:AH25,"LOW")>0),"EXCLUDE",IF(OR(AJ25<>"INCLUDE",F25<>"SUCCESS",D25<>"STORED",U25="",AP25="",AQ25="",AQ25="UNVERIFIED",AND(AP25="OFFICIAL_WEBSITE",Q25=""),AND(OR(AA25="Equipment manual / OEM instruction",AB25="Asset-specific normative"),OR(Z25<>"Manufacturer / supplier",AS25="",AC25=""))),"PENDING",IF(COUNTIF(AD25:AH25,"HIGH")=5,"INCLUDE","PENDING")))) | F25: SUCCESS | G25: 46262.531 | H25: 46262.531 | I25: INITIAL | J25: AUTO | K25: =IF(A25="","",IF(J25="AUTO",H25,IF(J25="MANUAL",AK25,""))) | L25: NONE | N25: =IF(A25="","",IF(COUNTIFS('Human Operation Desktop'!$A$3:$A$502,A25,'Human Operation Desktop'!$I$3:$I$502,"<>APPLIED",'Human Operation Desktop'!$I$3:$I$502,"<>REJECTED")>0,"YES","NO")) | O25: 3eb19d6be728a20e51a80ac13993de88c500c707580fa4b5eed19495d4871042 | P25: Nature Diversity Act | Q25: https://lovdata.no/dokument/NL/lov/2009-06-19-100 | R25: https://lovdata.no/dokument/NL/lov/2009-06-19-100 | S25: A_Public_Authority | T25: html | U25: Norwegian Ministry of Climate and Environment | V25: Norway | W25: Norwegian | Z25: Public authority | AA25: Law | AB25: Referenced normative | AC25: Official referenced source from Norwegian Ministry of Climate and Environment; included because an applicable law, permit or certification scheme may make its provisions binding within the approved scope. | AD25: HIGH | AE25: HIGH | AF25: HIGH | AG25: HIGH | AH25: HIGH | AI25: HIGH | AJ25: INCLUDE | AM25: CURRENT | AO25: Official expansion from environmental authority guidance; often relevant to permitting decisions and environmental assessment. | AP25: OFFICIAL_WEBSITE | AQ25: OFFICIAL_ORIGINAL | AR25: ROLLING
A26: PA024 | B26: PA024-001 | C26: PA024-001_Fiskeridirektoratet_guidance_to_NYTEK23.html | D26: STORED | E26: =IF(A26="","",IF(OR(AJ26="EXCLUDE",COUNTIF(AD26:AH26,"LOW")>0),"EXCLUDE",IF(OR(AJ26<>"INCLUDE",F26<>"SUCCESS",D26<>"STORED",U26="",AP26="",AQ26="",AQ26="UNVERIFIED",AND(AP26="OFFICIAL_WEBSITE",Q26=""),AND(OR(AA26="Equipment manual / OEM instruction",AB26="Asset-specific normative"),OR(Z26<>"Manufacturer / supplier",AS26="",AC26=""))),"PENDING",IF(COUNTIF(AD26:AH26,"HIGH")=5,"INCLUDE","PENDING")))) | F26: SUCCESS | G26: 46262.531 | H26: 46262.531 | I26: INITIAL | J26: AUTO | K26: =IF(A26="","",IF(J26="AUTO",H26,IF(J26="MANUAL",AK26,""))) | L26: NONE | N26: =IF(A26="","",IF(COUNTIFS('Human Operation Desktop'!$A$3:$A$502,A26,'Human Operation Desktop'!$I$3:$I$502,"<>APPLIED",'Human Operation Desktop'!$I$3:$I$502,"<>REJECTED")>0,"YES","NO")) | O26: e331c25d9cf82bf550a1e76076c3ad72ef36a37c8f04ca6b17d52d556753c375 | P26: Fiskeridirektoratet guidance to NYTEK23 | Q26: https://www.fiskeridir.no/akvakultur/veiledere/veileder-til-nytek23 | R26: https://www.fiskeridir.no/akvakultur/veiledere/veileder-til-nytek23 | S26: A_Public_Authority | T26: html | U26: Norwegian Directorate of Fisheries | V26: Norway | W26: Norwegian | Z26: Public authority | AA26: Interpretation document | AB26: Guidance / interpretation | AC26: Official guidance from Norwegian Directorate of Fisheries; included to interpret and operationalise linked normative requirements, not as independent legal or certification authority. | AD26: HIGH | AE26: HIGH | AF26: HIGH | AG26: HIGH | AH26: HIGH | AI26: HIGH | AJ26: INCLUDE | AM26: CURRENT | AN26: PA004 | AO26: Official guidance. It supports interpretation but does not replace PA004 or referenced standards. | AP26: OFFICIAL_WEBSITE | AQ26: OFFICIAL_ORIGINAL | AR26: ROLLING
A27: PA025 | B27: PA025-001 | C27: PA025-001_Guidance_on_holistic_risk_management_in_aquaculture.html | D27: STORED | E27: =IF(A27="","",IF(OR(AJ27="EXCLUDE",COUNTIF(AD27:AH27,"LOW")>0),"EXCLUDE",IF(OR(AJ27<>"INCLUDE",F27<>"SUCCESS",D27<>"STORED",U27="",AP27="",AQ27="",AQ27="UNVERIFIED",AND(AP27="OFFICIAL_WEBSITE",Q27=""),AND(OR(AA27="Equipment manual / OEM instruction",AB27="Asset-specific normative"),OR(Z27<>"Manufacturer / supplier",AS27="",AC27=""))),"PENDING",IF(COUNTIF(AD27:AH27,"HIGH")=5,"INCLUDE","PENDING")))) | F27: SUCCESS | G27: 46262.531 | H27: 46262.531 | I27: INITIAL | J27: AUTO | K27: =IF(A27="","",IF(J27="AUTO",H27,IF(J27="MANUAL",AK27,""))) | L27: NONE | N27: =IF(A27="","",IF(COUNTIFS('Human Operation Desktop'!$A$3:$A$502,A27,'Human Operation Desktop'!$I$3:$I$502,"<>APPLIED",'Human Operation Desktop'!$I$3:$I$502,"<>REJECTED")>0,"YES","NO")) | O27: 6b02f98209cd66f8d09b279dd0ba86c8cf84324e5d65599ca0c476490d10c801 | P27: Guidance on holistic risk management in aquaculture | Q27: https://www.fiskeridir.no/akvakultur/veiledere/veileder-helhetlig-risikostyring-innen-akvakultur | R27: https://www.fiskeridir.no/akvakultur/veiledere/veileder-helhetlig-risikostyring-innen-akvakultur | S27: A_Public_Authority | T27: html | U27: Norwegian Directorate of Fisheries | V27: Norway | W27: Norwegian | Z27: Public authority | AA27: Interpretation document | AB27: Guidance / interpretation | AC27: Official guidance from Norwegian Directorate of Fisheries; included to interpret and operationalise linked normative requirements, not as independent legal or certification authority. | AD27: HIGH | AE27: HIGH | AF27: HIGH | AG27: HIGH | AH27: HIGH | AI27: HIGH | AJ27: INCLUDE | AM27: CURRENT | AN27: PA016 | AO27: Official expansion source map. Useful for discovery and interpretation; not independently normative. | AP27: OFFICIAL_WEBSITE | AQ27: OFFICIAL_ORIGINAL | AR27: ROLLING
A28: PA026 | B28: PA026-001 | C28: PA026-001_Environmental_authority_guidance_on_aquaculture_pollution_management.html | D28: STORED | E28: =IF(A28="","",IF(OR(AJ28="EXCLUDE",COUNTIF(AD28:AH28,"LOW")>0),"EXCLUDE",IF(OR(AJ28<>"INCLUDE",F28<>"SUCCESS",D28<>"STORED",U28="",AP28="",AQ28="",AQ28="UNVERIFIED",AND(AP28="OFFICIAL_WEBSITE",Q28=""),AND(OR(AA28="Equipment manual / OEM instruction",AB28="Asset-specific normative"),OR(Z28<>"Manufacturer / supplier",AS28="",AC28=""))),"PENDING",IF(COUNTIF(AD28:AH28,"HIGH")=5,"INCLUDE","PENDING")))) | F28: SUCCESS | G28: 46262.531 | H28: 46262.531 | I28: INITIAL | J28: AUTO | K28: =IF(A28="","",IF(J28="AUTO",H28,IF(J28="MANUAL",AK28,""))) | L28: NONE | N28: =IF(A28="","",IF(COUNTIFS('Human Operation Desktop'!$A$3:$A$502,A28,'Human Operation Desktop'!$I$3:$I$502,"<>APPLIED",'Human Operation Desktop'!$I$3:$I$502,"<>REJECTED")>0,"YES","NO")) | O28: b21a5486fb976b28eaab6a693a453e5e39ccf551e5b0fe3dbfc376f923b028a1 | P28: Environmental authority guidance on aquaculture pollution management | Q28: https://www.miljodirektoratet.no/ansvarsomrader/forurensning/akvakultur/akvakultur-forvaltning/ | R28: https://www.miljodirektoratet.no/ansvarsomrader/forurensning/akvakultur/akvakultur-forvaltning/ | S28: A_Public_Authority | T28: html | U28: Norwegian Environment Agency | V28: Norway | W28: Norwegian | Z28: Public authority | AA28: Interpretation document | AB28: Guidance / interpretation | AC28: Official guidance from Norwegian Environment Agency; included to interpret and operationalise linked normative requirements, not as independent legal or certification authority. | AD28: HIGH | AE28: HIGH | AF28: HIGH | AG28: HIGH | AH28: HIGH | AI28: HIGH | AJ28: INCLUDE | AM28: CURRENT | AN28: PA007 | AO28: Official expansion. Identifies pollution-law, permit and monitoring relationships. | AP28: OFFICIAL_WEBSITE | AQ28: OFFICIAL_ORIGINAL | AR28: ROLLING
A29: PA027 | B29: PA027-001 | C29: PA027-001_Mattilsynet_fish_welfare_guidance_hub.html | D29: STORED | E29: =IF(A29="","",IF(OR(AJ29="EXCLUDE",COUNTIF(AD29:AH29,"LOW")>0),"EXCLUDE",IF(OR(AJ29<>"INCLUDE",F29<>"SUCCESS",D29<>"STORED",U29="",AP29="",AQ29="",AQ29="UNVERIFIED",AND(AP29="OFFICIAL_WEBSITE",Q29=""),AND(OR(AA29="Equipment manual / OEM instruction",AB29="Asset-specific normative"),OR(Z29<>"Manufacturer / supplier",AS29="",AC29=""))),"PENDING",IF(COUNTIF(AD29:AH29,"HIGH")=5,"INCLUDE","PENDING")))) | F29: SUCCESS | G29: 46262.531 | H29: 46262.531 | I29: INITIAL | J29: AUTO | K29: =IF(A29="","",IF(J29="AUTO",H29,IF(J29="MANUAL",AK29,""))) | L29: NONE | N29: =IF(A29="","",IF(COUNTIFS('Human Operation Desktop'!$A$3:$A$502,A29,'Human Operation Desktop'!$I$3:$I$502,"<>APPLIED",'Human Operation Desktop'!$I$3:$I$502,"<>REJECTED")>0,"YES","NO")) | O29: 32a13fc92400f9d3afede91b9772367087a32fcd4bb72541cf576b4f2367e4dd | P29: Mattilsynet fish welfare guidance hub | Q29: https://www.mattilsynet.no/fisk-og-akvakultur/fiskevelferd | R29: https://www.mattilsynet.no/fisk-og-akvakultur/fiskevelferd | S29: A_Public_Authority | T29: html | U29: Norwegian Food Safety Authority | V29: Norway | W29: Norwegian | Z29: Public authority | AA29: Interpretation document | AB29: Guidance / interpretation | AC29: Official guidance from Norwegian Food Safety Authority; included to interpret and operationalise linked normative requirements, not as independent legal or certification authority. | AD29: HIGH | AE29: HIGH | AF29: HIGH | AG29: HIGH | AH29: HIGH | AI29: HIGH | AJ29: INCLUDE | AM29: CURRENT | AN29: PA005 | AO29: Official expansion hub. Child guidance pages may later become separate sources when directly applicable. | AP29: OFFICIAL_WEBSITE | AQ29: OFFICIAL_ORIGINAL | AR29: ROLLING
A30: PA028 | B30: PA028-001 | C30: PA028-001_Norwegian_Aquaculture_Register.html | D30: STORED | E30: =IF(A30="","",IF(OR(AJ30="EXCLUDE",COUNTIF(AD30:AH30,"LOW")>0),"EXCLUDE",IF(OR(AJ30<>"INCLUDE",F30<>"SUCCESS",D30<>"STORED",U30="",AP30="",AQ30="",AQ30="UNVERIFIED",AND(AP30="OFFICIAL_WEBSITE",Q30=""),AND(OR(AA30="Equipment manual / OEM instruction",AB30="Asset-specific normative"),OR(Z30<>"Manufacturer / supplier",AS30="",AC30=""))),"PENDING",IF(COUNTIF(AD30:AH30,"HIGH")=5,"INCLUDE","PENDING")))) | F30: SUCCESS | G30: 46262.531 | H30: 46262.531 | I30: INITIAL | J30: AUTO | K30: =IF(A30="","",IF(J30="AUTO",H30,IF(J30="MANUAL",AK30,""))) | L30: NONE | N30: =IF(A30="","",IF(COUNTIFS('Human Operation Desktop'!$A$3:$A$502,A30,'Human Operation Desktop'!$I$3:$I$502,"<>APPLIED",'Human Operation Desktop'!$I$3:$I$502,"<>REJECTED")>0,"YES","NO")) | O30: e4b0fe39d80e5dff689ac77b143523e86d5c40228f73405a6c9171ee40462790 | P30: Norwegian Aquaculture Register | Q30: https://www.fiskeridir.no/registre/akvakulturregisteret | R30: https://www.fiskeridir.no/registre/akvakulturregisteret | S30: A_Public_Authority | T30: html | U30: Norwegian Directorate of Fisheries | V30: Norway | W30: Norwegian | Z30: Public authority | AA30: Other | AB30: Context / evidence | AC30: Official context source from Norwegian Directorate of Fisheries; included for applicability, site identity or source discovery, not for generating standalone requirements. | AD30: HIGH | AE30: MEDIUM | AF30: HIGH | AG30: HIGH | AH30: HIGH | AI30: HIGH | AJ30: PENDING | AM30: CURRENT | AN30: PA032 | AO30: Official expansion. Applicability and site identity source, not a primary source of normative text. | AP30: OFFICIAL_WEBSITE | AQ30: OFFICIAL_ORIGINAL | AR30: ROLLING
